Workbook

Sheet 0 - Instructions
A1: How to Use This Workbook
A2: Sheet | B2: Purpose | C2: What to do
A3: 0 - Instructions | B3: This sheet | C3: Read before starting.
A4: 1 - Mix Reference | B4: Lists all 12 SCBA mixes (SCBA 0–25% × NaOH 4M / 6M) with Fly Ash / GGBS split | C4: Enter the 28-day strength (MPa) of each mix once Batch 1 provides it. Enter it ONCE — Sheet 2 picks it up automatically.
A5: 2 - Raw Data Entry | B5: Main data entry sheet — 144 rows (12 mixes × 4 temperatures × 3 replicates) | C5: Fill YELLOW cells during or immediately after testing. GREEN cells calculate automatically.
A6: 3 - Graphs (Auto) | B6: 12 automatic bar charts and curve diagrams, placed before the results tables | C6: No entry needed. Charts redraw themselves as data is typed into Sheet 2.
A7: 4 - Residual Strength Summary | B7: Auto-summary — residual strength % per mix per temperature (average of 3 replicates) | C7: No manual entry needed. Also shows the best mix at each temperature.
A8: 5 - Mass Loss Summary | B8: Auto-summary — mass loss % per mix per temperature (average of 3 replicates) | C8: No manual entry needed.
A9: 6 - Visual Observations Log | B9: Written record of colour, cracking, spalling for each specimen | C9: Fill YELLOW cells after each fire batch.
A10: 7 - Schedule & Checklist | B10: Week-by-week testing plan + pre-test checklist | C10: Tick off checklist items before starting. Mark completed batches.
A11: 8 - Chart Data | B11: Helper tables that feed the charts (formulas only) | C11: Do not edit. Grey 'N/A' cells simply mean 'data not entered yet' — this keeps chart lines from dropping to zero.
A13: COLOUR LEGEND
A14: Yellow cells | B14: INPUT — you must fill these in manually
A15: Green cells | B15: AUTO-CALCULATED — do not type here; formula fills automatically
A16: Blue header | B16: Column/section header
A17: Orange | B17: Important notice, warning, or key mix (M9)
A19: WORKED EXAMPLE — specimen M9-600-3 (values are for illustration only; not part of the data set)
A20: Item | B20: Value | C20: How it is calculated
A21: Pre-fire mass (g) | B21: 2452 | C21: Input — digital balance before furnace loading
A22: Post-fire mass (g) | B22: 2270 | C22: Input — after complete natural cooling
A23: Failure load (kN) | B23: 305 | C23: Input — read from CTM display
A24: 28-day strength (MPa) | B24: 38.6 | C24: Input — from Batch 1, entered in Sheet 1
A25: Mass loss (%) | B25: =(B21-B22)/B21*100 -> 7.4225122 | C25: ((Pre − Post) ÷ Pre) × 100
A26: Failure load (N) | B26: =B23*1000 -> 305000 | C26: kN × 1000
A27: Residual comp. strength (MPa) | B27: =B26/10000 -> 30.5 | C27: Failure load (N) ÷ 10,000 mm² (100 mm cube face area)
A28: Residual strength (%) | B28: =B27/B24*100 -> 79.015544 | C28: (Post-fire MPa ÷ 28-day MPa) × 100

Sheet 1 - Mix Reference
A1: SCGPC Fire Resistance Study — Mix Reference Table
A2: 12 SCBA mixes prepared by M.Tech student | B.Tech Batch 2 — C Section | Fly Ash : GGBS = 70 : 30 of the remaining binder | Na₂SiO₃ : NaOH = 1 | SCBA replaces the TOTAL Fly Ash–GGBS binder by weight
A3: Mix ID | B3: SCBA Replacement (%) | C3: NaOH Molarity | D3: Fly Ash (%) [auto] | E3: GGBS (%) [auto] | F3: Category | G3: Notes | H3: 28-Day Strength (MPa) [from Batch 1 — fill in]
A4: M0 | B4: 0 | C4: 4M | D4: =(100-B4)*0.7 -> 70 | E4: =(100-B4)*0.3 -> 30 | F4: Control | G4: Baseline — no SCBA, FA:GGBS 70:30
A5: M1 | B5: 5 | C5: 4M | D5: =(100-B5)*0.7 -> 66.5 | E5: =(100-B5)*0.3 -> 28.5 | F5: SCBA 4M
A6: M2 | B6: 10 | C6: 4M | D6: =(100-B6)*0.7 -> 63 | E6: =(100-B6)*0.3 -> 27 | F6: SCBA 4M
A7: M3 | B7: 15 | C7: 4M | D7: =(100-B7)*0.7 -> 59.5 | E7: =(100-B7)*0.3 -> 25.5 | F7: SCBA 4M
A8: M4 | B8: 20 | C8: 4M | D8: =(100-B8)*0.7 -> 56 | E8: =(100-B8)*0.3 -> 24 | F8: SCBA 4M
A9: M5 | B9: 25 | C9: 4M | D9: =(100-B9)*0.7 -> 52.5 | E9: =(100-B9)*0.3 -> 22.5 | F9: SCBA 4M | G9: Upper bound — watch workability
A10: M6 | B10: 0 | C10: 6M | D10: =(100-B10)*0.7 -> 70 | E10: =(100-B10)*0.3 -> 30 | F10: Control | G10: Baseline — no SCBA, FA:GGBS 70:30
A11: M7 | B11: 5 | C11: 6M | D11: =(100-B11)*0.7 -> 66.5 | E11: =(100-B11)*0.3 -> 28.5 | F11: SCBA 6M
A12: M8 | B12: 10 | C12: 6M | D12: =(100-B12)*0.7 -> 63 | E12: =(100-B12)*0.3 -> 27 | F12: SCBA 6M
A13: M9 | B13: 15 | C13: 6M | D13: =(100-B13)*0.7 -> 59.5 | E13: =(100-B13)*0.3 -> 25.5 | F13: SCBA 6M | G13: Likely optimum — key mix
A14: M10 | B14: 20 | C14: 6M | D14: =(100-B14)*0.7 -> 56 | E14: =(100-B14)*0.3 -> 24 | F14: SCBA 6M
A15: M11 | B15: 25 | C15: 6M | D15: =(100-B15)*0.7 -> 52.5 | E15: =(100-B15)*0.3 -> 22.5 | F15: SCBA 6M | G15: Upper bound — watch workability
A17: Example of SCBA logic: a mix at 10% SCBA has 90% Fly Ash + GGBS (split 70 : 30 → 63.0% Fly Ash, 27.0% GGBS) plus 10% SCBA. Total specimens = 12 mixes × 4 temperatures × 3 replicates = 144 cubes.

Sheet 2 - Raw Data Entry
A1: SCGPC Fire Resistance — Raw Data Entry Sheet
A2: Fill YELLOW cells during testing. GREEN cells are auto-calculated. Never enter data from memory — fill on the same day as testing. Cube = 100 mm (area 10,000 mm²). Cool naturally — NEVER quench with water.
A3: SPECIMEN IDENTIFICATION | D3: PRE-FIRE | F3: POST-FIRE | J3: STRENGTH TESTING (CTM) | M3: CALCULATED RESULTS
A4: Mix ID | B4: Temperature (°C) | C4: Replicate (1/2/3) | D4: Pre-Fire Mass (g) | E4: Pre-Fire Condition Notes | F4: Post-Fire Mass (g) | G4: Colour Change | H4: Surface Cracks (Y/N) | I4: Spalling (Y/N) | J4: Failure Load (kN) | K4: Failure Load (N) [auto] | L4: 28-Day Strength (MPa) [auto] | M4: Mass Loss (%) [auto] | N4: Residual Comp. Str. (MPa) [auto] | O4: Residual Strength (%) [auto] | P4: Photo Reference (filename)
A5: M0 | B5: 200 | C5: 1 | K5: =IF(J5="","",J5*1000) | L5: =IF(INDEX('1 - Mix Reference'!$H$4:$H$15,MATCH(A5,'1 - Mix Reference'!$A$4:$A$15,0))="","",INDEX('1 - Mix Reference'!$H$4:$H$15,MATCH(A5,'1 - Mix Reference'!$A$4:$A$15,0))) | M5: =IF(OR(D5="",F5=""),"",((D5-F5)/D5)*100) | N5: =IF(K5="","",K5/10000) | O5: =IF(OR(N5="",L5=""),"",(N5/L5)*100)
A6: M0 | B6: 200 | C6: 2 | K6: =IF(J6="","",J6*1000) | L6: =IF(INDEX('1 - Mix Reference'!$H$4:$H$15,MATCH(A6,'1 - Mix Reference'!$A$4:$A$15,0))="","",INDEX('1 - Mix Reference'!$H$4:$H$15,MATCH(A6,'1 - Mix Reference'!$A$4:$A$15,0))) | M6: =IF(OR(D6="",F6=""),"",((D6-F6)/D6)*100) | N6: =IF(K6="","",K6/10000) | O6: =IF(OR(N6="",L6=""),"",(N6/L6)*100)
A7: M0 | B7: 200 | C7: 3 | K7: =IF(J7="","",J7*1000) | L7: =IF(INDEX('1 - Mix Reference'!$H$4:$H$15,MATCH(A7,'1 - Mix Reference'!$A$4:$A$15,0))="","",INDEX('1 - Mix Reference'!$H$4:$H$15,MATCH(A7,'1 - Mix Reference'!$A$4:$A$15,0))) | M7: =IF(OR(D7="",F7=""),"",((D7-F7)/D7)*100) | N7: =IF(K7="","",K7/10000) | O7: =IF(OR(N7="",L7=""),"",(N7/L7)*100)
A8: M1 | B8: 200 | C8: 1 | K8: =IF(J8="","",J8*1000) | L8: =IF(INDEX('1 - Mix Reference'!$H$4:$H$15,MATCH(A8,'1 - Mix Reference'!$A$4:$A$15,0))="","",INDEX('1 - Mix Reference'!$H$4:$H$15,MATCH(A8,'1 - Mix Reference'!$A$4:$A$15,0))) | M8: =IF(OR(D8="",F8=""),"",((D8-F8)/D8)*100) | N8: =IF(K8="","",K8/10000) | O8: =IF(OR(N8="",L8=""),"",(N8/L8)*100)
A9: M1 | B9: 200 | C9: 2 | K9: =IF(J9="","",J9*1000) | L9: =IF(INDEX('1 - Mix Reference'!$H$4:$H$15,MATCH(A9,'1 - Mix Reference'!$A$4:$A$15,0))="","",INDEX('1 - Mix Reference'!$H$4:$H$15,MATCH(A9,'1 - Mix Reference'!$A$4:$A$15,0))) | M9: =IF(OR(D9="",F9=""),"",((D9-F9)/D9)*100) | N9: =IF(K9="","",K9/10000) | O9: =IF(OR(N9="",L9=""),"",(N9/L9)*100)
A10: M1 | B10: 200 | C10: 3 | K10: =IF(J10="","",J10*1000) | L10: =IF(INDEX('1 - Mix Reference'!$H$4:$H$15,MATCH(A10,'1 - Mix Reference'!$A$4:$A$15,0))="","",INDEX('1 - Mix Reference'!$H$4:$H$15,MATCH(A10,'1 - Mix Reference'!$A$4:$A$15,0))) | M10: =IF(OR(D10="",F10=""),"",((D10-F10)/D10)*100) | N10: =IF(K10="","",K10/10000) | O10: =IF(OR(N10="",L10=""),"",(N10/L10)*100)
A11: M2 | B11: 200 | C11: 1 | K11: =IF(J11="","",J11*1000) | L11: =IF(INDEX('1 - Mix Reference'!$H$4:$H$15,MATCH(A11,'1 - Mix Reference'!$A$4:$A$15,0))="","",INDEX('1 - Mix Reference'!$H$4:$H$15,MATCH(A11,'1 - Mix Reference'!$A$4:$A$15,0))) | M11: =IF(OR(D11="",F11=""),"",((D11-F11)/D11)*100) | N11: =IF(K11="","",K11/10000) | O11: =IF(OR(N11="",L11=""),"",(N11/L11)*100)
A12: M2 | B12: 200 | C12: 2 | K12: =IF(J12="","",J12*1000) | L12: =IF(INDEX('1 - Mix Reference'!$H$4:$H$15,MATCH(A12,'1 - Mix Reference'!$A$4:$A$15,0))="","",INDEX('1 - Mix Reference'!$H$4:$H$15,MATCH(A12,'1 - Mix Reference'!$A$4:$A$15,0))) | M12: =IF(OR(D12="",F12=""),"",((D12-F12)/D12)*100) | N12: =IF(K12="","",K12/10000) | O12: =IF(OR(N12="",L12=""),"",(N12/L12)*100)
A13: M2 | B13: 200 | C13: 3 | K13: =IF(J13="","",J13*1000) | L13: =IF(INDEX('1 - Mix Reference'!$H$4:$H$15,MATCH(A13,'1 - Mix Reference'!$A$4:$A$15,0))="","",INDEX('1 - Mix Reference'!$H$4:$H$15,MATCH(A13,'1 - Mix Reference'!$A$4:$A$15,0))) | M13: =IF(OR(D13="",F13=""),"",((D13-F13)/D13)*100) | N13: =IF(K13="","",K13/10000) | O13: =IF(OR(N13="",L13=""),"",(N13/L13)*100)
A14: M3 | B14: 200 | C14: 1 | K14: =IF(J14="","",J14*1000) | L14: =IF(INDEX('1 - Mix Reference'!$H$4:$H$15,MATCH(A14,'1 - Mix Reference'!$A$4:$A$15,0))="","",INDEX('1 - Mix Reference'!$H$4:$H$15,MATCH(A14,'1 - Mix Reference'!$A$4:$A$15,0))) | M14: =IF(OR(D14="",F14=""),"",((D14-F14)/D14)*100) | N14: =IF(K14="","",K14/10000) | O14: =IF(OR(N14="",L14=""),"",(N14/L14)*100)
A15: M3 | B15: 200 | C15: 2 | K15: =IF(J15="","",J15*1000) | L15: =IF(INDEX('1 - Mix Reference'!$H$4:$H$15,MATCH(A15,'1 - Mix Reference'!$A$4:$A$15,0))="","",INDEX('1 - Mix Reference'!$H$4:$H$15,MATCH(A15,'1 - Mix Reference'!$A$4:$A$15,0))) | M15: =IF(OR(D15="",F15=""),"",((D15-F15)/D15)*100) | N15: =IF(K15="","",K15/10000) | O15: =IF(OR(N15="",L15=""),"",(N15/L15)*100)
A16: M3 | B16: 200 | C16: 3 | K16: =IF(J16="","",J16*1000) | L16: =IF(INDEX('1 - Mix Reference'!$H$4:$H$15,MATCH(A16,'1 - Mix Reference'!$A$4:$A$15,0))="","",INDEX('1 - Mix Reference'!$H$4:$H$15,MATCH(A16,'1 - Mix Reference'!$A$4:$A$15,0))) | M16: =IF(OR(D16="",F16=""),"",((D16-F16)/D16)*100) | N16: =IF(K16="","",K16/10000) | O16: =IF(OR(N16="",L16=""),"",(N16/L16)*100)
... A148: M11 | B148: 800 | C148: 3 | K148: =IF(J148="","",J148*1000) | L148: =IF(INDEX('1 - Mix Reference'!$H$4:$H$15,MATCH(A148,'1 - Mix Reference'!$A$4:$A$15,0))="","",INDEX('1 - Mix Reference'!$H$4:$H$15,MATCH(A148,'1 - Mix Reference'!$A$4:$A$15,0))) | M148: =IF(OR(D148="",F148=""),"",((D148-F148)/D148)*100) | N148: =IF(K148="","",K148/10000) | O148: =IF(OR(N148="",L148=""),"",(N148/L148)*100)

Sheet 3 - Graphs (Auto)
A1: Automatic Graphs — Bar Charts & Curve Diagrams
A2: All charts redraw automatically as data is entered in Sheet 2. Empty charts simply mean no data has been entered yet. Source tables: Sheet 8 (Chart Data). Detailed results tables follow in Sheets 4 and 5.
A4: A. CURVE DIAGRAMS — Residual strength (%) vs Temperature
A25: B. CURVE DIAGRAMS — Effect of SCBA replacement level at each temperature
A46: C. CURVE DIAGRAMS — Mass loss (%) vs Temperature
A67: D. BAR CHARTS — Comparison of all 12 mixes (clustered by temperature)
A108: E. KEY COMPARISONS — Control vs key mix, and NaOH 4M vs 6M

Sheet 4 - Residual Strength Summary
A1: Residual Strength Summary — Average per Mix per Temperature
A2: Values are AVERAGE of 3 replicates. Residual Strength % = (Post-fire MPa ÷ Original 28-day MPa) × 100. This table is the central finding of the research paper. Shows 'Data pending' until all 3 replicates are entered.
A3: Mix ID | B3: Category | C3: 200°C Residual Str (%) | D3: 400°C Residual Str (%) | E3: 600°C Residual Str (%) | F3: 800°C Residual Str (%) | G3: Notes
A4: M0 | B4: Control | 4M | C4: =IF(COUNT('2 - Raw Data Entry'!O5:O7)<3,"Data pending",AVERAGE('2 - Raw Data Entry'!O5:O7)) -> Data pending | D4: =IF(COUNT('2 - Raw Data Entry'!O41:O43)<3,"Data pending",AVERAGE('2 - Raw Data Entry'!O41:O43)) -> Data pending | E4: =IF(COUNT('2 - Raw Data Entry'!O77:O79)<3,"Data pending",AVERAGE('2 - Raw Data Entry'!O77:O79)) -> Data pending | F4: =IF(COUNT('2 - Raw Data Entry'!O113:O115)<3,"Data pending",AVERAGE('2 - Raw Data Entry'!O113:O115)) -> Data pending | G4: Baseline — no SCBA, FA:GGBS 70:30
A5: M1 | B5: SCBA 5% | 4M | C5: =IF(COUNT('2 - Raw Data Entry'!O8:O10)<3,"Data pending",AVERAGE('2 - Raw Data Entry'!O8:O10)) -> Data pending | D5: =IF(COUNT('2 - Raw Data Entry'!O44:O46)<3,"Data pending",AVERAGE('2 - Raw Data Entry'!O44:O46)) -> Data pending | E5: =IF(COUNT('2 - Raw Data Entry'!O80:O82)<3,"Data pending",AVERAGE('2 - Raw Data Entry'!O80:O82)) -> Data pending | F5: =IF(COUNT('2 - Raw Data Entry'!O116:O118)<3,"Data pending",AVERAGE('2 - Raw Data Entry'!O116:O118)) -> Data pending
A6: M2 | B6: SCBA 10% | 4M | C6: =IF(COUNT('2 - Raw Data Entry'!O11:O13)<3,"Data pending",AVERAGE('2 - Raw Data Entry'!O11:O13)) -> Data pending | D6: =IF(COUNT('2 - Raw Data Entry'!O47:O49)<3,"Data pending",AVERAGE('2 - Raw Data Entry'!O47:O49)) -> Data pending | E6: =IF(COUNT('2 - Raw Data Entry'!O83:O85)<3,"Data pending",AVERAGE('2 - Raw Data Entry'!O83:O85)) -> Data pending | F6: =IF(COUNT('2 - Raw Data Entry'!O119:O121)<3,"Data pending",AVERAGE('2 - Raw Data Entry'!O119:O121)) -> Data pending
A7: M3 | B7: SCBA 15% | 4M | C7: =IF(COUNT('2 - Raw Data Entry'!O14:O16)<3,"Data pending",AVERAGE('2 - Raw Data Entry'!O14:O16)) -> Data pending | D7: =IF(COUNT('2 - Raw Data Entry'!O50:O52)<3,"Data pending",AVERAGE('2 - Raw Data Entry'!O50:O52)) -> Data pending | E7: =IF(COUNT('2 - Raw Data Entry'!O86:O88)<3,"Data pending",AVERAGE('2 - Raw Data Entry'!O86:O88)) -> Data pending | F7: =IF(COUNT('2 - Raw Data Entry'!O122:O124)<3,"Data pending",AVERAGE('2 - Raw Data Entry'!O122:O124)) -> Data pending
A8: M4 | B8: SCBA 20% | 4M | C8: =IF(COUNT('2 - Raw Data Entry'!O17:O19)<3,"Data pending",AVERAGE('2 - Raw Data Entry'!O17:O19)) -> Data pending | D8: =IF(COUNT('2 - Raw Data Entry'!O53:O55)<3,"Data pending",AVERAGE('2 - Raw Data Entry'!O53:O55)) -> Data pending | E8: =IF(COUNT('2 - Raw Data Entry'!O89:O91)<3,"Data pending",AVERAGE('2 - Raw Data Entry'!O89:O91)) -> Data pending | F8: =IF(COUNT('2 - Raw Data Entry'!O125:O127)<3,"Data pending",AVERAGE('2 - Raw Data Entry'!O125:O127)) -> Data pending
A9: M5 | B9: SCBA 25% | 4M | C9: =IF(COUNT('2 - Raw Data Entry'!O20:O22)<3,"Data pending",AVERAGE('2 - Raw Data Entry'!O20:O22)) -> Data pending | D9: =IF(COUNT('2 - Raw Data Entry'!O56:O58)<3,"Data pending",AVERAGE('2 - Raw Data Entry'!O56:O58)) -> Data pending | E9: =IF(COUNT('2 - Raw Data Entry'!O92:O94)<3,"Data pending",AVERAGE('2 - Raw Data Entry'!O92:O94)) -> Data pending | F9: =IF(COUNT('2 - Raw Data Entry'!O128:O130)<3,"Data pending",AVERAGE('2 - Raw Data Entry'!O128:O130)) -> Data pending | G9: Upper bound — watch workability
A10: M6 | B10: Control | 6M | C10: =IF(COUNT('2 - Raw Data Entry'!O23:O25)<3,"Data pending",AVERAGE('2 - Raw Data Entry'!O23:O25)) -> Data pending | D10: =IF(COUNT('2 - Raw Data Entry'!O59:O61)<3,"Data pending",AVERAGE('2 - Raw Data Entry'!O59:O61)) -> Data pending | E10: =IF(COUNT('2 - Raw Data Entry'!O95:O97)<3,"Data pending",AVERAGE('2 - Raw Data Entry'!O95:O97)) -> Data pending | F10: =IF(COUNT('2 - Raw Data Entry'!O131:O133)<3,"Data pending",AVERAGE('2 - Raw Data Entry'!O131:O133)) -> Data pending | G10: Baseline — no SCBA, FA:GGBS 70:30
A11: M7 | B11: SCBA 5% | 6M | C11: =IF(COUNT('2 - Raw Data Entry'!O26:O28)<3,"Data pending",AVERAGE('2 - Raw Data Entry'!O26:O28)) -> Data pending | D11: =IF(COUNT('2 - Raw Data Entry'!O62:O64)<3,"Data pending",AVERAGE('2 - Raw Data Entry'!O62:O64)) -> Data pending | E11: =IF(COUNT('2 - Raw Data Entry'!O98:O100)<3,"Data pending",AVERAGE('2 - Raw Data Entry'!O98:O100)) -> Data pending | F11: =IF(COUNT('2 - Raw Data Entry'!O134:O136)<3,"Data pending",AVERAGE('2 - Raw Data Entry'!O134:O136)) -> Data pending
A12: M8 | B12: SCBA 10% | 6M | C12: =IF(COUNT('2 - Raw Data Entry'!O29:O31)<3,"Data pending",AVERAGE('2 - Raw Data Entry'!O29:O31)) -> Data pending | D12: =IF(COUNT('2 - Raw Data Entry'!O65:O67)<3,"Data pending",AVERAGE('2 - Raw Data Entry'!O65:O67)) -> Data pending | E12: =IF(COUNT('2 - Raw Data Entry'!O101:O103)<3,"Data pending",AVERAGE('2 - Raw Data Entry'!O101:O103)) -> Data pending | F12: =IF(COUNT('2 - Raw Data Entry'!O137:O139)<3,"Data pending",AVERAGE('2 - Raw Data Entry'!O137:O139)) -> Data pending
A13: M9 | B13: SCBA 15% | 6M | C13: =IF(COUNT('2 - Raw Data Entry'!O32:O34)<3,"Data pending",AVERAGE('2 - Raw Data Entry'!O32:O34)) -> Data pending | D13: =IF(COUNT('2 - Raw Data Entry'!O68:O70)<3,"Data pending",AVERAGE('2 - Raw Data Entry'!O68:O70)) -> Data pending | E13: =IF(COUNT('2 - Raw Data Entry'!O104:O106)<3,"Data pending",AVERAGE('2 - Raw Data Entry'!O104:O106)) -> Data pending | F13: =IF(COUNT('2 - Raw Data Entry'!O140:O142)<3,"Data pending",AVERAGE('2 - Raw Data Entry'!O140:O142)) -> Data pending | G13: Likely optimum — key mix
A14: M10 | B14: SCBA 20% | 6M | C14: =IF(COUNT('2 - Raw Data Entry'!O35:O37)<3,"Data pending",AVERAGE('2 - Raw Data Entry'!O35:O37)) -> Data pending | D14: =IF(COUNT('2 - Raw Data Entry'!O71:O73)<3,"Data pending",AVERAGE('2 - Raw Data Entry'!O71:O73)) -> Data pending | E14: =IF(COUNT('2 - Raw Data Entry'!O107:O109)<3,"Data pending",AVERAGE('2 - Raw Data Entry'!O107:O109)) -> Data pending | F14: =IF(COUNT('2 - Raw Data Entry'!O143:O145)<3,"Data pending",AVERAGE('2 - Raw Data Entry'!O143:O145)) -> Data pending
A15: M11 | B15: SCBA 25% | 6M | C15: =IF(COUNT('2 - Raw Data Entry'!O38:O40)<3,"Data pending",AVERAGE('2 - Raw Data Entry'!O38:O40)) -> Data pending | D15: =IF(COUNT('2 - Raw Data Entry'!O74:O76)<3,"Data pending",AVERAGE('2 - Raw Data Entry'!O74:O76)) -> Data pending | E15: =IF(COUNT('2 - Raw Data Entry'!O110:O112)<3,"Data pending",AVERAGE('2 - Raw Data Entry'!O110:O112)) -> Data pending | F15: =IF(COUNT('2 - Raw Data Entry'!O146:O148)<3,"Data pending",AVERAGE('2 - Raw Data Entry'!O146:O148)) -> Data pending | G15: Upper bound — watch workability
A17: Best mix (highest residual %) | C17: =IFERROR(INDEX($A$4:$A$15,MATCH(MAX(C4:C15),C4:C15,0)),"—") -> — | D17: =IFERROR(INDEX($A$4:$A$15,MATCH(MAX(D4:D15),D4:D15,0)),"—") -> — | E17: =IFERROR(INDEX($A$4:$A$15,MATCH(MAX(E4:E15),E4:E15,0)),"—") -> — | F17: =IFERROR(INDEX($A$4:$A$15,MATCH(MAX(F4:F15),F4:F15,0)),"—") -> — | G17: Auto — updates as data is entered

Sheet 5 - Mass Loss Summary
A1: Mass Loss Summary — Average per Mix per Temperature
A2: Mass Loss % = ((Pre-fire mass − Post-fire mass) ÷ Pre-fire mass) × 100 | Values are average of 3 replicates.
A3: Mix ID | B3: Category | C3: 200°C Mass Loss (%) | D3: 400°C Mass Loss (%) | E3: 600°C Mass Loss (%) | F3: 800°C Mass Loss (%) | G3: Notes
A4: M0 | B4: Control | 4M | C4: =IF(COUNT('2 - Raw Data Entry'!M5:M7)<3,"Data pending",AVERAGE('2 - Raw Data Entry'!M5:M7)) -> Data pending | D4: =IF(COUNT('2 - Raw Data Entry'!M41:M43)<3,"Data pending",AVERAGE('2 - Raw Data Entry'!M41:M43)) -> Data pending | E4: =IF(COUNT('2 - Raw Data Entry'!M77:M79)<3,"Data pending",AVERAGE('2 - Raw Data Entry'!M77:M79)) -> Data pending | F4: =IF(COUNT('2 - Raw Data Entry'!M113:M115)<3,"Data pending",AVERAGE('2 - Raw Data Entry'!M113:M115)) -> Data pending | G4: Baseline — no SCBA, FA:GGBS 70:30
A5: M1 | B5: SCBA 5% | 4M | C5: =IF(COUNT('2 - Raw Data Entry'!M8:M10)<3,"Data pending",AVERAGE('2 - Raw Data Entry'!M8:M10)) -> Data pending | D5: =IF(COUNT('2 - Raw Data Entry'!M44:M46)<3,"Data pending",AVERAGE('2 - Raw Data Entry'!M44:M46)) -> Data pending | E5: =IF(COUNT('2 - Raw Data Entry'!M80:M82)<3,"Data pending",AVERAGE('2 - Raw Data Entry'!M80:M82)) -> Data pending | F5: =IF(COUNT('2 - Raw Data Entry'!M116:M118)<3,"Data pending",AVERAGE('2 - Raw Data Entry'!M116:M118)) -> Data pending
A6: M2 | B6: SCBA 10% | 4M | C6: =IF(COUNT('2 - Raw Data Entry'!M11:M13)<3,"Data pending",AVERAGE('2 - Raw Data Entry'!M11:M13)) -> Data pending | D6: =IF(COUNT('2 - Raw Data Entry'!M47:M49)<3,"Data pending",AVERAGE('2 - Raw Data Entry'!M47:M49)) -> Data pending | E6: =IF(COUNT('2 - Raw Data Entry'!M83:M85)<3,"Data pending",AVERAGE('2 - Raw Data Entry'!M83:M85)) -> Data pending | F6: =IF(COUNT('2 - Raw Data Entry'!M119:M121)<3,"Data pending",AVERAGE('2 - Raw Data Entry'!M119:M121)) -> Data pending
A7: M3 | B7: SCBA 15% | 4M | C7: =IF(COUNT('2 - Raw Data Entry'!M14:M16)<3,"Data pending",AVERAGE('2 - Raw Data Entry'!M14:M16)) -> Data pending | D7: =IF(COUNT('2 - Raw Data Entry'!M50:M52)<3,"Data pending",AVERAGE('2 - Raw Data Entry'!M50:M52)) -> Data pending | E7: =IF(COUNT('2 - Raw Data Entry'!M86:M88)<3,"Data pending",AVERAGE('2 - Raw Data Entry'!M86:M88)) -> Data pending | F7: =IF(COUNT('2 - Raw Data Entry'!M122:M124)<3,"Data pending",AVERAGE('2 - Raw Data Entry'!M122:M124)) -> Data pending
A8: M4 | B8: SCBA 20% | 4M | C8: =IF(COUNT('2 - Raw Data Entry'!M17:M19)<3,"Data pending",AVERAGE('2 - Raw Data Entry'!M17:M19)) -> Data pending | D8: =IF(COUNT('2 - Raw Data Entry'!M53:M55)<3,"Data pending",AVERAGE('2 - Raw Data Entry'!M53:M55)) -> Data pending | E8: =IF(COUNT('2 - Raw Data Entry'!M89:M91)<3,"Data pending",AVERAGE('2 - Raw Data Entry'!M89:M91)) -> Data pending | F8: =IF(COUNT('2 - Raw Data Entry'!M125:M127)<3,"Data pending",AVERAGE('2 - Raw Data Entry'!M125:M127)) -> Data pending
A9: M5 | B9: SCBA 25% | 4M | C9: =IF(COUNT('2 - Raw Data Entry'!M20:M22)<3,"Data pending",AVERAGE('2 - Raw Data Entry'!M20:M22)) -> Data pending | D9: =IF(COUNT('2 - Raw Data Entry'!M56:M58)<3,"Data pending",AVERAGE('2 - Raw Data Entry'!M56:M58)) -> Data pending | E9: =IF(COUNT('2 - Raw Data Entry'!M92:M94)<3,"Data pending",AVERAGE('2 - Raw Data Entry'!M92:M94)) -> Data pending | F9: =IF(COUNT('2 - Raw Data Entry'!M128:M130)<3,"Data pending",AVERAGE('2 - Raw Data Entry'!M128:M130)) -> Data pending | G9: Upper bound — watch workability
A10: M6 | B10: Control | 6M | C10: =IF(COUNT('2 - Raw Data Entry'!M23:M25)<3,"Data pending",AVERAGE('2 - Raw Data Entry'!M23:M25)) -> Data pending | D10: =IF(COUNT('2 - Raw Data Entry'!M59:M61)<3,"Data pending",AVERAGE('2 - Raw Data Entry'!M59:M61)) -> Data pending | E10: =IF(COUNT('2 - Raw Data Entry'!M95:M97)<3,"Data pending",AVERAGE('2 - Raw Data Entry'!M95:M97)) -> Data pending | F10: =IF(COUNT('2 - Raw Data Entry'!M131:M133)<3,"Data pending",AVERAGE('2 - Raw Data Entry'!M131:M133)) -> Data pending | G10: Baseline — no SCBA, FA:GGBS 70:30
A11: M7 | B11: SCBA 5% | 6M | C11: =IF(COUNT('2 - Raw Data Entry'!M26:M28)<3,"Data pending",AVERAGE('2 - Raw Data Entry'!M26:M28)) -> Data pending | D11: =IF(COUNT('2 - Raw Data Entry'!M62:M64)<3,"Data pending",AVERAGE('2 - Raw Data Entry'!M62:M64)) -> Data pending | E11: =IF(COUNT('2 - Raw Data Entry'!M98:M100)<3,"Data pending",AVERAGE('2 - Raw Data Entry'!M98:M100)) -> Data pending | F11: =IF(COUNT('2 - Raw Data Entry'!M134:M136)<3,"Data pending",AVERAGE('2 - Raw Data Entry'!M134:M136)) -> Data pending
A12: M8 | B12: SCBA 10% | 6M | C12: =IF(COUNT('2 - Raw Data Entry'!M29:M31)<3,"Data pending",AVERAGE('2 - Raw Data Entry'!M29:M31)) -> Data pending | D12: =IF(COUNT('2 - Raw Data Entry'!M65:M67)<3,"Data pending",AVERAGE('2 - Raw Data Entry'!M65:M67)) -> Data pending | E12: =IF(COUNT('2 - Raw Data Entry'!M101:M103)<3,"Data pending",AVERAGE('2 - Raw Data Entry'!M101:M103)) -> Data pending | F12: =IF(COUNT('2 - Raw Data Entry'!M137:M139)<3,"Data pending",AVERAGE('2 - Raw Data Entry'!M137:M139)) -> Data pending
A13: M9 | B13: SCBA 15% | 6M | C13: =IF(COUNT('2 - Raw Data Entry'!M32:M34)<3,"Data pending",AVERAGE('2 - Raw Data Entry'!M32:M34)) -> Data pending | D13: =IF(COUNT('2 - Raw Data Entry'!M68:M70)<3,"Data pending",AVERAGE('2 - Raw Data Entry'!M68:M70)) -> Data pending | E13: =IF(COUNT('2 - Raw Data Entry'!M104:M106)<3,"Data pending",AVERAGE('2 - Raw Data Entry'!M104:M106)) -> Data pending | F13: =IF(COUNT('2 - Raw Data Entry'!M140:M142)<3,"Data pending",AVERAGE('2 - Raw Data Entry'!M140:M142)) -> Data pending | G13: Likely optimum — key mix
A14: M10 | B14: SCBA 20% | 6M | C14: =IF(COUNT('2 - Raw Data Entry'!M35:M37)<3,"Data pending",AVERAGE('2 - Raw Data Entry'!M35:M37)) -> Data pending | D14: =IF(COUNT('2 - Raw Data Entry'!M71:M73)<3,"Data pending",AVERAGE('2 - Raw Data Entry'!M71:M73)) -> Data pending | E14: =IF(COUNT('2 - Raw Data Entry'!M107:M109)<3,"Data pending",AVERAGE('2 - Raw Data Entry'!M107:M109)) -> Data pending | F14: =IF(COUNT('2 - Raw Data Entry'!M143:M145)<3,"Data pending",AVERAGE('2 - Raw Data Entry'!M143:M145)) -> Data pending
A15: M11 | B15: SCBA 25% | 6M | C15: =IF(COUNT('2 - Raw Data Entry'!M38:M40)<3,"Data pending",AVERAGE('2 - Raw Data Entry'!M38:M40)) -> Data pending | D15: =IF(COUNT('2 - Raw Data Entry'!M74:M76)<3,"Data pending",AVERAGE('2 - Raw Data Entry'!M74:M76)) -> Data pending | E15: =IF(COUNT('2 - Raw Data Entry'!M110:M112)<3,"Data pending",AVERAGE('2 - Raw Data Entry'!M110:M112)) -> Data pending | F15: =IF(COUNT('2 - Raw Data Entry'!M146:M148)<3,"Data pending",AVERAGE('2 - Raw Data Entry'!M146:M148)) -> Data pending | G15: Upper bound — watch workability
A17: Lowest mass loss (best mix) | C17: =IFERROR(INDEX($A$4:$A$15,MATCH(MIN(C4:C15),C4:C15,0)),"—") -> — | D17: =IFERROR(INDEX($A$4:$A$15,MATCH(MIN(D4:D15),D4:D15,0)),"—") -> — | E17: =IFERROR(INDEX($A$4:$A$15,MATCH(MIN(E4:E15),E4:E15,0)),"—") -> — | F17: =IFERROR(INDEX($A$4:$A$15,MATCH(MIN(F4:F15),F4:F15,0)),"—") -> — | G17: Auto — updates as data is entered

Sheet 6 - Visual Observations Log
A1: Visual Observations Log — Post-Fire Appearance
A2: Colour guide: White/Grey = moderate heating | Brown/Reddish ≈ 400°C | Dark grey ≥ 600°C. Record for every specimen (144 rows).
A3: Specimen Label (Mix-Temp-Rep) | B3: Mix ID | C3: Temperature (°C) | D3: Replicate | E3: Colour Description | F3: Cracks (None/Minor/Major) | G3: Spalling (None/Partial/Severe) | H3: Additional Notes
A4: M0-200-1 | B4: M0 | C4: 200 | D4: 1
A5: M0-200-2 | B5: M0 | C5: 200 | D5: 2
A6: M0-200-3 | B6: M0 | C6: 200 | D6: 3
A7: M1-200-1 | B7: M1 | C7: 200 | D7: 1
A8: M1-200-2 | B8: M1 | C8: 200 | D8: 2
A9: M1-200-3 | B9: M1 | C9: 200 | D9: 3
A10: M2-200-1 | B10: M2 | C10: 200 | D10: 1
A11: M2-200-2 | B11: M2 | C11: 200 | D11: 2
A12: M2-200-3 | B12: M2 | C12: 200 | D12: 3
A13: M3-200-1 | B13: M3 | C13: 200 | D13: 1
A14: M3-200-2 | B14: M3 | C14: 200 | D14: 2
A15: M3-200-3 | B15: M3 | C15: 200 | D15: 3
... A147: M11-800-3 | B147: M11 | C147: 800 | D147: 3

Sheet 7 - Schedule & Checklist
A1: Testing Schedule & Completion Checklist — Weeks 14–16
A2: Week | B2: Temperature Batch | C2: Cubes | D2: Task Description | E2: Completed? (Y/N) | F2: Specimens tested [auto]
A3: Week 14 | B3: 200°C | C3: 36 | D3: Trial run first — verify procedure and equipment. Fire 12 mixes × 3 replicates at 200°C (5–10°C/min, hold 2 hrs). Cool naturally. Weigh, photograph, test CTM. Record all data. | F3: =COUNT('2 - Raw Data Entry'!J5:J40)&" / 36" -> 0 / 36
A4: Week 14 | B4: 400°C | C4: 36 | D4: After 200°C batch is complete. Fire 12 mixes × 3 replicates at 400°C. Cool naturally. Weigh, photograph, test CTM. Record all data. | F4: =COUNT('2 - Raw Data Entry'!J41:J76)&" / 36" -> 0 / 36
A5: Week 15 | B5: 600°C | C5: 36 | D5: Expect visible colour changes and some cracking. Allow longer cooling. Weigh, photograph, test CTM. Record all data. | F5: =COUNT('2 - Raw Data Entry'!J77:J112)&" / 36" -> 0 / 36
A6: Week 16 | B6: 800°C | C6: 36 | D6: Most extreme exposure. Some mixes may show spalling and significant mass loss. Document everything carefully. Hand over data to M.Tech student. | F6: =COUNT('2 - Raw Data Entry'!J113:J148)&" / 36" -> 0 / 36
A8: PRE-TEST CHECKLIST
A9: ☐ | B9: Furnace booked for all 3 weeks (Week 14, 15, 16) — 3-week blockout confirmed
A10: ☐ | B10: 28-day strength values received from M.Tech student (for all 12 mixes) and entered in Sheet 1
A11: ☐ | B11: Excel data sheet prepared and labelled
A12: ☐ | B12: Digital balance available and calibrated
A13: ☐ | B13: CTM (Compression Testing Machine) available and calibrated — loading rate 2.5 kN/s
A14: ☐ | B14: Heat-resistant gloves, tongs and safety goggles available
A15: ☐ | B15: Camera / phone ready for photographs
A16: ☐ | B16: Lab ventilation confirmed for 600°C and 800°C runs
A17: ☐ | B17: All 144 cubes received and verified from M.Tech student
A18: ☐ | B18: All cubes labelled: Mix ID — Temperature — Replicate number (e.g., M3-400-2)
A20: ⚠ NEVER quench specimens with water. Natural air cooling only. Do not exceed 10°C/min heating rate. Never touch hot specimens with bare hands.

Sheet 8 - Chart Data
A1: Chart Data — helper tables that feed the charts on Sheet 3 (do not edit)
A2: Grey N/A values = data not yet entered. This is intentional: charts leave a gap instead of plotting zero. Everything here is formula-driven from Sheets 1, 4 and 5 and from the raw data.
A3: T1 — Residual strength (%) per mix
A4: Mix | B4: 200°C | C4: 400°C | D4: 600°C | E4: 800°C | F4: SCBA %
A5: M0 | B5: =IF(ISNUMBER('4 - Residual Strength Summary'!C4),'4 - Residual Strength Summary'!C4,NA()) -> #N/A | C5: =IF(ISNUMBER('4 - Residual Strength Summary'!D4),'4 - Residual Strength Summary'!D4,NA()) -> #N/A | D5: =IF(ISNUMBER('4 - Residual Strength Summary'!E4),'4 - Residual Strength Summary'!E4,NA()) -> #N/A | E5: =IF(ISNUMBER('4 - Residual Strength Summary'!F4),'4 - Residual Strength Summary'!F4,NA()) -> #N/A | F5: ='1 - Mix Reference'!B4 -> 0
A6: M1 | B6: =IF(ISNUMBER('4 - Residual Strength Summary'!C5),'4 - Residual Strength Summary'!C5,NA()) -> #N/A | C6: =IF(ISNUMBER('4 - Residual Strength Summary'!D5),'4 - Residual Strength Summary'!D5,NA()) -> #N/A | D6: =IF(ISNUMBER('4 - Residual Strength Summary'!E5),'4 - Residual Strength Summary'!E5,NA()) -> #N/A | E6: =IF(ISNUMBER('4 - Residual Strength Summary'!F5),'4 - Residual Strength Summary'!F5,NA()) -> #N/A | F6: ='1 - Mix Reference'!B5 -> 5
A7: M2 | B7: =IF(ISNUMBER('4 - Residual Strength Summary'!C6),'4 - Residual Strength Summary'!C6,NA()) -> #N/A | C7: =IF(ISNUMBER('4 - Residual Strength Summary'!D6),'4 - Residual Strength Summary'!D6,NA()) -> #N/A | D7: =IF(ISNUMBER('4 - Residual Strength Summary'!E6),'4 - Residual Strength Summary'!E6,NA()) -> #N/A | E7: =IF(ISNUMBER('4 - Residual Strength Summary'!F6),'4 - Residual Strength Summary'!F6,NA()) -> #N/A | F7: ='1 - Mix Reference'!B6 -> 10
A8: M3 | B8: =IF(ISNUMBER('4 - Residual Strength Summary'!C7),'4 - Residual Strength Summary'!C7,NA()) -> #N/A | C8: =IF(ISNUMBER('4 - Residual Strength Summary'!D7),'4 - Residual Strength Summary'!D7,NA()) -> #N/A | D8: =IF(ISNUMBER('4 - Residual Strength Summary'!E7),'4 - Residual Strength Summary'!E7,NA()) -> #N/A | E8: =IF(ISNUMBER('4 - Residual Strength Summary'!F7),'4 - Residual Strength Summary'!F7,NA()) -> #N/A | F8: ='1 - Mix Reference'!B7 -> 15
A9: M4 | B9: =IF(ISNUMBER('4 - Residual Strength Summary'!C8),'4 - Residual Strength Summary'!C8,NA()) -> #N/A | C9: =IF(ISNUMBER('4 - Residual Strength Summary'!D8),'4 - Residual Strength Summary'!D8,NA()) -> #N/A | D9: =IF(ISNUMBER('4 - Residual Strength Summary'!E8),'4 - Residual Strength Summary'!E8,NA()) -> #N/A | E9: =IF(ISNUMBER('4 - Residual Strength Summary'!F8),'4 - Residual Strength Summary'!F8,NA()) -> #N/A | F9: ='1 - Mix Reference'!B8 -> 20
A10: M5 | B10: =IF(ISNUMBER('4 - Residual Strength Summary'!C9),'4 - Residual Strength Summary'!C9,NA()) -> #N/A | C10: =IF(ISNUMBER('4 - Residual Strength Summary'!D9),'4 - Residual Strength Summary'!D9,NA()) -> #N/A | D10: =IF(ISNUMBER('4 - Residual Strength Summary'!E9),'4 - Residual Strength Summary'!E9,NA()) -> #N/A | E10: =IF(ISNUMBER('4 - Residual Strength Summary'!F9),'4 - Residual Strength Summary'!F9,NA()) -> #N/A | F10: ='1 - Mix Reference'!B9 -> 25
A11: M6 | B11: =IF(ISNUMBER('4 - Residual Strength Summary'!C10),'4 - Residual Strength Summary'!C10,NA()) -> #N/A | C11: =IF(ISNUMBER('4 - Residual Strength Summary'!D10),'4 - Residual Strength Summary'!D10,NA()) -> #N/A | D11: =IF(ISNUMBER('4 - Residual Strength Summary'!E10),'4 - Residual Strength Summary'!E10,NA()) -> #N/A | E11: =IF(ISNUMBER('4 - Residual Strength Summary'!F10),'4 - Residual Strength Summary'!F10,NA()) -> #N/A | F11: ='1 - Mix Reference'!B10 -> 0
A12: M7 | B12: =IF(ISNUMBER('4 - Residual Strength Summary'!C11),'4 - Residual Strength Summary'!C11,NA()) -> #N/A | C12: =IF(ISNUMBER('4 - Residual Strength Summary'!D11),'4 - Residual Strength Summary'!D11,NA()) -> #N/A | D12: =IF(ISNUMBER('4 - Residual Strength Summary'!E11),'4 - Residual Strength Summary'!E11,NA()) -> #N/A | E12: =IF(ISNUMBER('4 - Residual Strength Summary'!F11),'4 - Residual Strength Summary'!F11,NA()) -> #N/A | F12: ='1 - Mix Reference'!B11 -> 5
A13: M8 | B13: =IF(ISNUMBER('4 - Residual Strength Summary'!C12),'4 - Residual Strength Summary'!C12,NA()) -> #N/A | C13: =IF(ISNUMBER('4 - Residual Strength Summary'!D12),'4 - Residual Strength Summary'!D12,NA()) -> #N/A | D13: =IF(ISNUMBER('4 - Residual Strength Summary'!E12),'4 - Residual Strength Summary'!E12,NA()) -> #N/A | E13: =IF(ISNUMBER('4 - Residual Strength Summary'!F12),'4 - Residual Strength Summary'!F12,NA()) -> #N/A | F13: ='1 - Mix Reference'!B12 -> 10
A14: M9 | B14: =IF(ISNUMBER('4 - Residual Strength Summary'!C13),'4 - Residual Strength Summary'!C13,NA()) -> #N/A | C14: =IF(ISNUMBER('4 - Residual Strength Summary'!D13),'4 - Residual Strength Summary'!D13,NA()) -> #N/A | D14: =IF(ISNUMBER('4 - Residual Strength Summary'!E13),'4 - Residual Strength Summary'!E13,NA()) -> #N/A | E14: =IF(ISNUMBER('4 - Residual Strength Summary'!F13),'4 - Residual Strength Summary'!F13,NA()) -> #N/A | F14: ='1 - Mix Reference'!B13 -> 15
A15: M10 | B15: =IF(ISNUMBER('4 - Residual Strength Summary'!C14),'4 - Residual Strength Summary'!C14,NA()) -> #N/A | C15: =IF(ISNUMBER('4 - Residual Strength Summary'!D14),'4 - Residual Strength Summary'!D14,NA()) -> #N/A | D15: =IF(ISNUMBER('4 - Residual Strength Summary'!E14),'4 - Residual Strength Summary'!E14,NA()) -> #N/A | E15: =IF(ISNUMBER('4 - Residual Strength Summary'!F14),'4 - Residual Strength Summary'!F14,NA()) -> #N/A | F15: ='1 - Mix Reference'!B14 -> 20
A16: M11 | B16: =IF(ISNUMBER('4 - Residual Strength Summary'!C15),'4 - Residual Strength Summary'!C15,NA()) -> #N/A | C16: =IF(ISNUMBER('4 - Residual Strength Summary'!D15),'4 - Residual Strength Summary'!D15,NA()) -> #N/A | D16: =IF(ISNUMBER('4 - Residual Strength Summary'!E15),'4 - Residual Strength Summary'!E15,NA()) -> #N/A | E16: =IF(ISNUMBER('4 - Residual Strength Summary'!F15),'4 - Residual Strength Summary'!F15,NA()) -> #N/A | F16: ='1 - Mix Reference'!B15 -> 25
A19: T2 — Mass loss (%) per mix
A20: Mix | B20: 200°C | C20: 400°C | D20: 600°C | E20: 800°C | F20: SCBA %
A21: M0 | B21: =IF(ISNUMBER('5 - Mass Loss Summary'!C4),'5 - Mass Loss Summary'!C4,NA()) -> #N/A | C21: =IF(ISNUMBER('5 - Mass Loss Summary'!D4),'5 - Mass Loss Summary'!D4,NA()) -> #N/A | D21: =IF(ISNUMBER('5 - Mass Loss Summary'!E4),'5 - Mass Loss Summary'!E4,NA()) -> #N/A | E21: =IF(ISNUMBER('5 - Mass Loss Summary'!F4),'5 - Mass Loss Summary'!F4,NA()) -> #N/A | F21: ='1 - Mix Reference'!B4 -> 0
A22: M1 | B22: =IF(ISNUMBER('5 - Mass Loss Summary'!C5),'5 - Mass Loss Summary'!C5,NA()) -> #N/A | C22: =IF(ISNUMBER('5 - Mass Loss Summary'!D5),'5 - Mass Loss Summary'!D5,NA()) -> #N/A | D22: =IF(ISNUMBER('5 - Mass Loss Summary'!E5),'5 - Mass Loss Summary'!E5,NA()) -> #N/A | E22: =IF(ISNUMBER('5 - Mass Loss Summary'!F5),'5 - Mass Loss Summary'!F5,NA()) -> #N/A | F22: ='1 - Mix Reference'!B5 -> 5
A23: M2 | B23: =IF(ISNUMBER('5 - Mass Loss Summary'!C6),'5 - Mass Loss Summary'!C6,NA()) -> #N/A | C23: =IF(ISNUMBER('5 - Mass Loss Summary'!D6),'5 - Mass Loss Summary'!D6,NA()) -> #N/A | D23: =IF(ISNUMBER('5 - Mass Loss Summary'!E6),'5 - Mass Loss Summary'!E6,NA()) -> #N/A | E23: =IF(ISNUMBER('5 - Mass Loss Summary'!F6),'5 - Mass Loss Summary'!F6,NA()) -> #N/A | F23: ='1 - Mix Reference'!B6 -> 10
A24: M3 | B24: =IF(ISNUMBER('5 - Mass Loss Summary'!C7),'5 - Mass Loss Summary'!C7,NA()) -> #N/A | C24: =IF(ISNUMBER('5 - Mass Loss Summary'!D7),'5 - Mass Loss Summary'!D7,NA()) -> #N/A | D24: =IF(ISNUMBER('5 - Mass Loss Summary'!E7),'5 - Mass Loss Summary'!E7,NA()) -> #N/A | E24: =IF(ISNUMBER('5 - Mass Loss Summary'!F7),'5 - Mass Loss Summary'!F7,NA()) -> #N/A | F24: ='1 - Mix Reference'!B7 -> 15
A25: M4 | B25: =IF(ISNUMBER('5 - Mass Loss Summary'!C8),'5 - Mass Loss Summary'!C8,NA()) -> #N/A | C25: =IF(ISNUMBER('5 - Mass Loss Summary'!D8),'5 - Mass Loss Summary'!D8,NA()) -> #N/A | D25: =IF(ISNUMBER('5 - Mass Loss Summary'!E8),'5 - Mass Loss Summary'!E8,NA()) -> #N/A | E25: =IF(ISNUMBER('5 - Mass Loss Summary'!F8),'5 - Mass Loss Summary'!F8,NA()) -> #N/A | F25: ='1 - Mix Reference'!B8 -> 20
A26: M5 | B26: =IF(ISNUMBER('5 - Mass Loss Summary'!C9),'5 - Mass Loss Summary'!C9,NA()) -> #N/A | C26: =IF(ISNUMBER('5 - Mass Loss Summary'!D9),'5 - Mass Loss Summary'!D9,NA()) -> #N/A | D26: =IF(ISNUMBER('5 - Mass Loss Summary'!E9),'5 - Mass Loss Summary'!E9,NA()) -> #N/A | E26: =IF(ISNUMBER('5 - Mass Loss Summary'!F9),'5 - Mass Loss Summary'!F9,NA()) -> #N/A | F26: ='1 - Mix Reference'!B9 -> 25
A27: M6 | B27: =IF(ISNUMBER('5 - Mass Loss Summary'!C10),'5 - Mass Loss Summary'!C10,NA()) -> #N/A | C27: =IF(ISNUMBER('5 - Mass Loss Summary'!D10),'5 - Mass Loss Summary'!D10,NA()) -> #N/A | D27: =IF(ISNUMBER('5 - Mass Loss Summary'!E10),'5 - Mass Loss Summary'!E10,NA()) -> #N/A | E27: =IF(ISNUMBER('5 - Mass Loss Summary'!F10),'5 - Mass Loss Summary'!F10,NA()) -> #N/A | F27: ='1 - Mix Reference'!B10 -> 0
A28: M7 | B28: =IF(ISNUMBER('5 - Mass Loss Summary'!C11),'5 - Mass Loss Summary'!C11,NA()) -> #N/A | C28: =IF(ISNUMBER('5 - Mass Loss Summary'!D11),'5 - Mass Loss Summary'!D11,NA()) -> #N/A | D28: =IF(ISNUMBER('5 - Mass Loss Summary'!E11),'5 - Mass Loss Summary'!E11,NA()) -> #N/A | E28: =IF(ISNUMBER('5 - Mass Loss Summary'!F11),'5 - Mass Loss Summary'!F11,NA()) -> #N/A | F28: ='1 - Mix Reference'!B11 -> 5
A29: M8 | B29: =IF(ISNUMBER('5 - Mass Loss Summary'!C12),'5 - Mass Loss Summary'!C12,NA()) -> #N/A | C29: =IF(ISNUMBER('5 - Mass Loss Summary'!D12),'5 - Mass Loss Summary'!D12,NA()) -> #N/A | D29: =IF(ISNUMBER('5 - Mass Loss Summary'!E12),'5 - Mass Loss Summary'!E12,NA()) -> #N/A | E29: =IF(ISNUMBER('5 - Mass Loss Summary'!F12),'5 - Mass Loss Summary'!F12,NA()) -> #N/A | F29: ='1 - Mix Reference'!B12 -> 10
A30: M9 | B30: =IF(ISNUMBER('5 - Mass Loss Summary'!C13),'5 - Mass Loss Summary'!C13,NA()) -> #N/A | C30: =IF(ISNUMBER('5 - Mass Loss Summary'!D13),'5 - Mass Loss Summary'!D13,NA()) -> #N/A | D30: =IF(ISNUMBER('5 - Mass Loss Summary'!E13),'5 - Mass Loss Summary'!E13,NA()) -> #N/A | E30: =IF(ISNUMBER('5 - Mass Loss Summary'!F13),'5 - Mass Loss Summary'!F13,NA()) -> #N/A | F30: ='1 - Mix Reference'!B13 -> 15
A31: M10 | B31: =IF(ISNUMBER('5 - Mass Loss Summary'!C14),'5 - Mass Loss Summary'!C14,NA()) -> #N/A | C31: =IF(ISNUMBER('5 - Mass Loss Summary'!D14),'5 - Mass Loss Summary'!D14,NA()) -> #N/A | D31: =IF(ISNUMBER('5 - Mass Loss Summary'!E14),'5 - Mass Loss Summary'!E14,NA()) -> #N/A | E31: =IF(ISNUMBER('5 - Mass Loss Summary'!F14),'5 - Mass Loss Summary'!F14,NA()) -> #N/A | F31: ='1 - Mix Reference'!B14 -> 20
A32: M11 | B32: =IF(ISNUMBER('5 - Mass Loss Summary'!C15),'5 - Mass Loss Summary'!C15,NA()) -> #N/A | C32: =IF(ISNUMBER('5 - Mass Loss Summary'!D15),'5 - Mass Loss Summary'!D15,NA()) -> #N/A | D32: =IF(ISNUMBER('5 - Mass Loss Summary'!E15),'5 - Mass Loss Summary'!E15,NA()) -> #N/A | E32: =IF(ISNUMBER('5 - Mass Loss Summary'!F15),'5 - Mass Loss Summary'!F15,NA()) -> #N/A | F32: ='1 - Mix Reference'!B15 -> 25
A35: T3 — Residual compressive strength (MPa), average of 3 replicates
A36: Mix | B36: 200°C | C36: 400°C | D36: 600°C | E36: 800°C | F36: SCBA %
A37: M0 | B37: =IF(COUNT('2 - Raw Data Entry'!N5:N7)<3,NA(),AVERAGE('2 - Raw Data Entry'!N5:N7)) -> #N/A | C37: =IF(COUNT('2 - Raw Data Entry'!N41:N43)<3,NA(),AVERAGE('2 - Raw Data Entry'!N41:N43)) -> #N/A | D37: =IF(COUNT('2 - Raw Data Entry'!N77:N79)<3,NA(),AVERAGE('2 - Raw Data Entry'!N77:N79)) -> #N/A | E37: =IF(COUNT('2 - Raw Data Entry'!N113:N115)<3,NA(),AVERAGE('2 - Raw Data Entry'!N113:N115)) -> #N/A | F37: ='1 - Mix Reference'!B4 -> 0
A38: M1 | B38: =IF(COUNT('2 - Raw Data Entry'!N8:N10)<3,NA(),AVERAGE('2 - Raw Data Entry'!N8:N10)) -> #N/A | C38: =IF(COUNT('2 - Raw Data Entry'!N44:N46)<3,NA(),AVERAGE('2 - Raw Data Entry'!N44:N46)) -> #N/A | D38: =IF(COUNT('2 - Raw Data Entry'!N80:N82)<3,NA(),AVERAGE('2 - Raw Data Entry'!N80:N82)) -> #N/A | E38: =IF(COUNT('2 - Raw Data Entry'!N116:N118)<3,NA(),AVERAGE('2 - Raw Data Entry'!N116:N118)) -> #N/A | F38: ='1 - Mix Reference'!B5 -> 5
A39: M2 | B39: =IF(COUNT('2 - Raw Data Entry'!N11:N13)<3,NA(),AVERAGE('2 - Raw Data Entry'!N11:N13)) -> #N/A | C39: =IF(COUNT('2 - Raw Data Entry'!N47:N49)<3,NA(),AVERAGE('2 - Raw Data Entry'!N47:N49)) -> #N/A | D39: =IF(COUNT('2 - Raw Data Entry'!N83:N85)<3,NA(),AVERAGE('2 - Raw Data Entry'!N83:N85)) -> #N/A | E39: =IF(COUNT('2 - Raw Data Entry'!N119:N121)<3,NA(),AVERAGE('2 - Raw Data Entry'!N119:N121)) -> #N/A | F39: ='1 - Mix Reference'!B6 -> 10
A40: M3 | B40: =IF(COUNT('2 - Raw Data Entry'!N14:N16)<3,NA(),AVERAGE('2 - Raw Data Entry'!N14:N16)) -> #N/A | C40: =IF(COUNT('2 - Raw Data Entry'!N50:N52)<3,NA(),AVERAGE('2 - Raw Data Entry'!N50:N52)) -> #N/A | D40: =IF(COUNT('2 - Raw Data Entry'!N86:N88)<3,NA(),AVERAGE('2 - Raw Data Entry'!N86:N88)) -> #N/A | E40: =IF(COUNT('2 - Raw Data Entry'!N122:N124)<3,NA(),AVERAGE('2 - Raw Data Entry'!N122:N124)) -> #N/A | F40: ='1 - Mix Reference'!B7 -> 15
A41: M4 | B41: =IF(COUNT('2 - Raw Data Entry'!N17:N19)<3,NA(),AVERAGE('2 - Raw Data Entry'!N17:N19)) -> #N/A | C41: =IF(COUNT('2 - Raw Data Entry'!N53:N55)<3,NA(),AVERAGE('2 - Raw Data Entry'!N53:N55)) -> #N/A | D41: =IF(COUNT('2 - Raw Data Entry'!N89:N91)<3,NA(),AVERAGE('2 - Raw Data Entry'!N89:N91)) -> #N/A | E41: =IF(COUNT('2 - Raw Data Entry'!N125:N127)<3,NA(),AVERAGE('2 - Raw Data Entry'!N125:N127)) -> #N/A | F41: ='1 - Mix Reference'!B8 -> 20
A42: M5 | B42: =IF(COUNT('2 - Raw Data Entry'!N20:N22)<3,NA(),AVERAGE('2 - Raw Data Entry'!N20:N22)) -> #N/A | C42: =IF(COUNT('2 - Raw Data Entry'!N56:N58)<3,NA(),AVERAGE('2 - Raw Data Entry'!N56:N58)) -> #N/A | D42: =IF(COUNT('2 - Raw Data Entry'!N92:N94)<3,NA(),AVERAGE('2 - Raw Data Entry'!N92:N94)) -> #N/A | E42: =IF(COUNT('2 - Raw Data Entry'!N128:N130)<3,NA(),AVERAGE('2 - Raw Data Entry'!N128:N130)) -> #N/A | F42: ='1 - Mix Reference'!B9 -> 25
A43: M6 | B43: =IF(COUNT('2 - Raw Data Entry'!N23:N25)<3,NA(),AVERAGE('2 - Raw Data Entry'!N23:N25)) -> #N/A | C43: =IF(COUNT('2 - Raw Data Entry'!N59:N61)<3,NA(),AVERAGE('2 - Raw Data Entry'!N59:N61)) -> #N/A | D43: =IF(COUNT('2 - Raw Data Entry'!N95:N97)<3,NA(),AVERAGE('2 - Raw Data Entry'!N95:N97)) -> #N/A | E43: =IF(COUNT('2 - Raw Data Entry'!N131:N133)<3,NA(),AVERAGE('2 - Raw Data Entry'!N131:N133)) -> #N/A | F43: ='1 - Mix Reference'!B10 -> 0
A44: M7 | B44: =IF(COUNT('2 - Raw Data Entry'!N26:N28)<3,NA(),AVERAGE('2 - Raw Data Entry'!N26:N28)) -> #N/A | C44: =IF(COUNT('2 - Raw Data Entry'!N62:N64)<3,NA(),AVERAGE('2 - Raw Data Entry'!N62:N64)) -> #N/A | D44: =IF(COUNT('2 - Raw Data Entry'!N98:N100)<3,NA(),AVERAGE('2 - Raw Data Entry'!N98:N100)) -> #N/A | E44: =IF(COUNT('2 - Raw Data Entry'!N134:N136)<3,NA(),AVERAGE('2 - Raw Data Entry'!N134:N136)) -> #N/A | F44: ='1 - Mix Reference'!B11 -> 5
...
